Workbook
Name NativeTimeline_Order_Date: #N/A
Name Slicer_Loyalty_card: #N/A
Name Slicer_Roast_Type_Name: #N/A
Name Slicer_Size: #N/A

Sheet Dashboard

Sheet TotalSales
A3: Sum of Sales | C3: Coffee Type name
A4: Years (Order Date) | B4: Months (Order Date) | C4: Arabica | D4: Excelsa | E4: Liberica | F4: Robusta
A5: 2019 | B5: Jan | D5: 107.73 | E5: 95.1 | F5: 11.94
B6: Feb | C6: 162.125 | D6: 88.21 | E6: 314.9 | F6: 100.24
B7: Mar | D7: 159.58 | E7: 75.69 | F7: 89.3
B8: Apr | C8: 242.37 | D8: 499.905 | E8: 104.65 | F8: 137.34
B9: May | D9: 75.735 | E9: 193.835 | F9: 68.04
B10: Jun | C10: 163.02 | D10: 130.625 | E10: 46.77 | F10: 281.52
B11: Jul | C11: 175.07 | D11: 55.19 | E11: 12.95 | F11: 59.7
B12: Aug | C12: 121.215 | D12: 29.7 | F12: 43.02
B13: Sep | D13: 130.35 | E13: 210.725 | F13: 457.08
B14: Oct | C14: 114.01 | D14: 39.69 | E14: 161.165
B15: Nov | C15: 245.335 | D15: 63.25 | E15: 126.5 | F15: 73.125
B16: Dec | C16: 17.385 | D16: 321.585 | E16: 137.85 | F16: 152.035
A17: 2020 | B17: Jan | C17: 47.25 | D17: 10.935 | E17: 231.88 | F17: 21.495
B18: Feb | C18: 5.97 | D18: 94.55 | E18: 73.74 | F18: 27.15
B19: Mar | C19: 63.81 | D19: 186.03 | E19: 200.345 | F19: 65.67
B20: Apr | D20: 269.5 | E20: 23.775 | F20: 125.615
B21: May | C21: 215.315 | D21: 296.055 | E21: 23.775 | F21: 14.925
B22: Jun | C22: 240.75 | D22: 165.715 | E22: 212.425 | F22: 140.88
B23: Jul | C23: 351.15 | D23: 117.425 | E23: 61.11 | F23: 147.675
B24: Aug | E24: 31.97 | F24: 11.94
B25: Sep | C25: 24.66 | E25: 25.05 | F25: 5.97
B26: Oct | C26: 278.155 | D26: 366.585 | E26: 305.74 | F26: 131.45
B27: Nov | C27: 349.945 | D27: 142.56 | E27: 227.9 | F27: 77.235
B28: Dec | C28: 71.98 | D28: 130.085 | E28: 23.31 | F28: 59.195
A29: 2021 | B29: Jan | C29: 151.875 | D29: 127.475 | E29: 78.63 | F29: 124.375
B30: Feb | C30: 172.2 | D30: 235.65 | E30: 7.77 | F30: 64.44
B31: Mar | C31: 225.9 | D31: 160.74 | E31: 126.91 | F31: 89.535
B32: Apr | C32: 39.42 | D32: 233.23 | E32: 225.925 | F32: 82.34
B33: May | C33: 91.5 | D33: 38.37 | E33: 3.885 | F33: 88.07
B34: Jun | C34: 150.685 | D34: 123.83 | E34: 21.825
B35: Jul | D35: 268.875 | E35: 8.73 | F35: 53.7
B36: Aug | C36: 168.105 | D36: 207.26 | F36: 175.55
B37: Sep | C37: 173.415 | D37: 238.275 | E37: 46.62 | F37: 35.85
B38: Oct | C38: 56.07 | E38: 299.07 | F38: 141.085
B39: Nov | C39: 260.01 | D39: 106.02 | E39: 262.72 | F39: 189.475
B40: Dec | C40: 197.615 | D40: 18.225 | E40: 241.85 | F40: 26.85
A41: 2022 | B41: Jan | C41: 82.635 | D41: 93.96 | E41: 380.435 | F41: 78.035
B42: Feb | C42: 65.67 | D42: 4.125 | E42: 23.775
...

Sheet Country Barchart
A4: Country | B4: Sum of Sales
A5: United Kingdom | B5: 2798.505
A6: Ireland | B6: 6696.865
A7: United States | B7: 35638.885

Sheet Top5Customers
A4: Customer Name | B4: Sum of Sales
A5: Don Flintiff | B5: 278.01
A6: Nealson Cuttler | B6: 281.675
A7: Terri Farra | B7: 289.11
A8: Brenn Dundredge | B8: 307.045
A9: Allis Wilmore | B9: 317.07

Sheet orders
A1: Order ID | B1: Order Date | C1: Customer ID | D1: Product ID | E1: Quantity | F1: Customer Name | G1: Email | H1: Country | I1: Coffee Type | J1: Roast Type | K1: Size | L1: Unit Price | M1: Sales | N1: Coffee Type name | O1: Roast Type Name | P1: Loyalty card
A2: QEV-37451-860 | B2: 43713 | C2: 17670-51384-MA | D2: R-M-1 | E2: 2 | F2: =_xlfn.XLOOKUP(C2,customers!$A$1:$A$1001,customers!$B$1:$B$1001,,0) -> Aloisia Allner | G2: =_xlfn.LET(_xlpm.val,_xlfn.XLOOKUP(C2,customers!$A$1:$A$1001,customers!$C$1:$C$1001,,0),IF(_xlpm.val=0,"",_xlpm.val)) -> aallner0@lulu.com | H2: =_xlfn.LET(_xlpm.val,_xlfn.XLOOKUP(C2,customers!$A$1:$A$1001,customers!$G$1:$G$1001,,0),IF(_xlpm.val=0,"",_xlpm.val)) -> United States | I2: =INDEX(products!$A$1:$G$49,MATCH(orders!$D2,products!$A$1:$A$49,0),MATCH(orders!I$1,products!$A$1:$G$1,0)) -> Rob | J2: =INDEX(products!$A$1:$G$49,MATCH(orders!$D2,products!$A$1:$A$49,0),MATCH(orders!J$1,products!$A$1:$G$1,0)) -> M | K2: =INDEX(products!$A$1:$G$49,MATCH(orders!$D2,products!$A$1:$A$49,0),MATCH(orders!K$1,products!$A$1:$G$1,0)) -> 1 | L2: =INDEX(products!$A$1:$G$49,MATCH(orders!$D2,products!$A$1:$A$49,0),MATCH(orders!L$1,products!$A$1:$G$1,0)) -> 9.95 | M2: =L2*E2 -> 19.9 | N2: {=_xlfn.SWITCH(I2,"rob","Robusta","exc","Excelsa","Ara","Arabica","Lib","Liberica","")} -> Robusta | O2: {=_xlfn.SWITCH(J2,"M","Medium","D","Dark","L","Light")} -> Medium | P2: =_xlfn.XLOOKUP(ORDERS[[#This Row],[Customer ID]],customers!$A$1:$A$1001,customers!$I$1:$I$1001,,0) -> Yes
A3: QEV-37451-860 | B3: 43713 | C3: 17670-51384-MA | D3: E-M-0.5 | E3: 5 | F3: =_xlfn.XLOOKUP(C3,customers!$A$1:$A$1001,customers!$B$1:$B$1001,,0) -> Aloisia Allner | G3: =_xlfn.LET(_xlpm.val,_xlfn.XLOOKUP(C3,customers!$A$1:$A$1001,customers!$C$1:$C$1001,,0),IF(_xlpm.val=0,"",_xlpm.val)) -> aallner0@lulu.com | H3: =_xlfn.LET(_xlpm.val,_xlfn.XLOOKUP(C3,customers!$A$1:$A$1001,customers!$G$1:$G$1001,,0),IF(_xlpm.val=0,"",_xlpm.val)) -> United States | I3: =INDEX(products!$A$1:$G$49,MATCH(orders!$D3,products!$A$1:$A$49,0),MATCH(orders!I$1,products!$A$1:$G$1,0)) -> Exc | J3: =INDEX(products!$A$1:$G$49,MATCH(orders!$D3,products!$A$1:$A$49,0),MATCH(orders!J$1,products!$A$1:$G$1,0)) -> M | K3: =INDEX(products!$A$1:$G$49,MATCH(orders!$D3,products!$A$1:$A$49,0),MATCH(orders!K$1,products!$A$1:$G$1,0)) -> 0.5 | L3: =INDEX(products!$A$1:$G$49,MATCH(orders!$D3,products!$A$1:$A$49,0),MATCH(orders!L$1,products!$A$1:$G$1,0)) -> 8.25 | M3: =L3*E3 -> 41.25 | N3: {=_xlfn.SWITCH(I3,"rob","Robusta","exc","Excelsa","Ara","Arabica","Lib","Liberica","")} -> Excelsa | O3: {=_xlfn.SWITCH(J3,"M","Medium","D","Dark","L","Light")} -> Medium | P3: =_xlfn.XLOOKUP(ORDERS[[#This Row],[Customer ID]],customers!$A$1:$A$1001,customers!$I$1:$I$1001,,0) -> Yes
A4: FAA-43335-268 | B4: 44364 | C4: 21125-22134-PX | D4: A-L-1 | E4: 1 | F4: =_xlfn.XLOOKUP(C4,customers!$A$1:$A$1001,customers!$B$1:$B$1001,,0) -> Jami Redholes | G4: =_xlfn.LET(_xlpm.val,_xlfn.XLOOKUP(C4,customers!$A$1:$A$1001,customers!$C$1:$C$1001,,0),IF(_xlpm.val=0,"",_xlpm.val)) -> jredholes2@tmall.com | H4: =_xlfn.LET(_xlpm.val,_xlfn.XLOOKUP(C4,customers!$A$1:$A$1001,customers!$G$1:$G$1001,,0),IF(_xlpm.val=0,"",_xlpm.val)) -> United States | I4: =INDEX(products!$A$1:$G$49,MATCH(orders!$D4,products!$A$1:$A$49,0),MATCH(orders!I$1,products!$A$1:$G$1,0)) -> Ara | J4: =INDEX(products!$A$1:$G$49,MATCH(orders!$D4,products!$A$1:$A$49,0),MATCH(orders!J$1,products!$A$1:$G$1,0)) -> L | K4: =INDEX(products!$A$1:$G$49,MATCH(orders!$D4,products!$A$1:$A$49,0),MATCH(orders!K$1,products!$A$1:$G$1,0)) -> 1 | L4: =INDEX(products!$A$1:$G$49,MATCH(orders!$D4,products!$A$1:$A$49,0),MATCH(orders!L$1,products!$A$1:$G$1,0)) -> 12.95 | M4: =L4*E4 -> 12.95 | N4: {=_xlfn.SWITCH(I4,"rob","Robusta","exc","Excelsa","Ara","Arabica","Lib","Liberica","")} -> Arabica | O4: {=_xlfn.SWITCH(J4,"M","Medium","D","Dark","L","Light")} -> Light | P4: =_xlfn.XLOOKUP(ORDERS[[#This Row],[Customer ID]],customers!$A$1:$A$1001,customers!$I$1:$I$1001,,0) -> Yes
A5: KAC-83089-793 | B5: 44392 | C5: 23806-46781-OU | D5: E-M-1 | E5: 2 | F5: =_xlfn.XLOOKUP(C5,customers!$A$1:$A$1001,customers!$B$1:$B$1001,,0) -> Christoffer O' Shea | G5: =_xlfn.LET(_xlpm.val,_xlfn.XLOOKUP(C5,customers!$A$1:$A$1001,customers!$C$1:$C$1001,,0),IF(_xlpm.val=0,"",_xlpm.val)) | H5: =_xlfn.LET(_xlpm.val,_xlfn.XLOOKUP(C5,customers!$A$1:$A$1001,customers!$G$1:$G$1001,,0),IF(_xlpm.val=0,"",_xlpm.val)) -> Ireland | I5: =INDEX(products!$A$1:$G$49,MATCH(orders!$D5,products!$A$1:$A$49,0),MATCH(orders!I$1,products!$A$1:$G$1,0)) -> Exc | J5: =INDEX(products!$A$1:$G$49,MATCH(orders!$D5,products!$A$1:$A$49,0),MATCH(orders!J$1,products!$A$1:$G$1,0)) -> M | K5: =INDEX(products!$A$1:$G$49,MATCH(orders!$D5,products!$A$1:$A$49,0),MATCH(orders!K$1,products!$A$1:$G$1,0)) -> 1 | L5: =INDEX(products!$A$1:$G$49,MATCH(orders!$D5,products!$A$1:$A$49,0),MATCH(orders!L$1,products!$A$1:$G$1,0)) -> 13.75 | M5: =L5*E5 -> 27.5 | N5: {=_xlfn.SWITCH(I5,"rob","Robusta","exc","Excelsa","Ara","Arabica","Lib","Liberica","")} -> Excelsa | O5: {=_xlfn.SWITCH(J5,"M","Medium","D","Dark","L","Light")} -> Medium | P5: =_xlfn.XLOOKUP(ORDERS[[#This Row],[Customer ID]],customers!$A$1:$A$1001,customers!$I$1:$I$1001,,0) -> No
A6: KAC-83089-793 | B6: 44392 | C6: 23806-46781-OU | D6: R-L-2.5 | E6: 2 | F6: =_xlfn.XLOOKUP(C6,customers!$A$1:$A$1001,customers!$B$1:$B$1001,,0) -> Christoffer O' Shea | G6: =_xlfn.LET(_xlpm.val,_xlfn.XLOOKUP(C6,customers!$A$1:$A$1001,customers!$C$1:$C$1001,,0),IF(_xlpm.val=0,"",_xlpm.val)) | H6: =_xlfn.LET(_xlpm.val,_xlfn.XLOOKUP(C6,customers!$A$1:$A$1001,customers!$G$1:$G$1001,,0),IF(_xlpm.val=0,"",_xlpm.val)) -> Ireland | I6: =INDEX(products!$A$1:$G$49,MATCH(orders!$D6,products!$A$1:$A$49,0),MATCH(orders!I$1,products!$A$1:$G$1,0)) -> Rob | J6: =INDEX(products!$A$1:$G$49,MATCH(orders!$D6,products!$A$1:$A$49,0),MATCH(orders!J$1,products!$A$1:$G$1,0)) -> L | K6: =INDEX(products!$A$1:$G$49,MATCH(orders!$D6,products!$A$1:$A$49,0),MATCH(orders!K$1,products!$A$1:$G$1,0)) -> 2.5 | L6: =INDEX(products!$A$1:$G$49,MATCH(orders!$D6,products!$A$1:$A$49,0),MATCH(orders!L$1,products!$A$1:$G$1,0)) -> 27.485 | M6: =L6*E6 -> 54.97 | N6: {=_xlfn.SWITCH(I6,"rob","Robusta","exc","Excelsa","Ara","Arabica","Lib","Liberica","")} -> Robusta | O6: {=_xlfn.SWITCH(J6,"M","Medium","D","Dark","L","Light")} -> Light | P6: =_xlfn.XLOOKUP(ORDERS[[#This Row],[Customer ID]],customers!$A$1:$A$1001,customers!$I$1:$I$1001,,0) -> No
A7: CVP-18956-553 | B7: 44412 | C7: 86561-91660-RB | D7: L-D-1 | E7: 3 | F7: =_xlfn.XLOOKUP(C7,customers!$A$1:$A$1001,customers!$B$1:$B$1001,,0) -> Beryle Cottier | G7: =_xlfn.LET(_xlpm.val,_xlfn.XLOOKUP(C7,customers!$A$1:$A$1001,customers!$C$1:$C$1001,,0),IF(_xlpm.val=0,"",_xlpm.val)) | H7: =_xlfn.LET(_xlpm.val,_xlfn.XLOOKUP(C7,customers!$A$1:$A$1001,customers!$G$1:$G$1001,,0),IF(_xlpm.val=0,"",_xlpm.val)) -> United States | I7: =INDEX(products!$A$1:$G$49,MATCH(orders!$D7,products!$A$1:$A$49,0),MATCH(orders!I$1,products!$A$1:$G$1,0)) -> Lib | J7: =INDEX(products!$A$1:$G$49,MATCH(orders!$D7,products!$A$1:$A$49,0),MATCH(orders!J$1,products!$A$1:$G$1,0)) -> D | K7: =INDEX(products!$A$1:$G$49,MATCH(orders!$D7,products!$A$1:$A$49,0),MATCH(orders!K$1,products!$A$1:$G$1,0)) -> 1 | L7: =INDEX(products!$A$1:$G$49,MATCH(orders!$D7,products!$A$1:$A$49,0),MATCH(orders!L$1,products!$A$1:$G$1,0)) -> 12.95 | M7: =L7*E7 -> 38.85 | N7: {=_xlfn.SWITCH(I7,"rob","Robusta","exc","Excelsa","Ara","Arabica","Lib","Liberica","")} -> Liberica | O7: {=_xlfn.SWITCH(J7,"M","Medium","D","Dark","L","Light")} -> Dark | P7: =_xlfn.XLOOKUP(ORDERS[[#This Row],[Customer ID]],customers!$A$1:$A$1001,customers!$I$1:$I$1001,,0) -> No
A8: IPP-31994-879 | B8: 44582 | C8: 65223-29612-CB | D8: E-D-0.5 | E8: 3 | F8: =_xlfn.XLOOKUP(C8,customers!$A$1:$A$1001,customers!$B$1:$B$1001,,0) -> Shaylynn Lobe | G8: =_xlfn.LET(_xlpm.val,_xlfn.XLOOKUP(C8,customers!$A$1:$A$1001,customers!$C$1:$C$1001,,0),IF(_xlpm.val=0,"",_xlpm.val)) -> slobe6@nifty.com | H8: =_xlfn.LET(_xlpm.val,_xlfn.XLOOKUP(C8,customers!$A$1:$A$1001,customers!$G$1:$G$1001,,0),IF(_xlpm.val=0,"",_xlpm.val)) -> United States | I8: =INDEX(products!$A$1:$G$49,MATCH(orders!$D8,products!$A$1:$A$49,0),MATCH(orders!I$1,products!$A$1:$G$1,0)) -> Exc | J8: =INDEX(products!$A$1:$G$49,MATCH(orders!$D8,products!$A$1:$A$49,0),MATCH(orders!J$1,products!$A$1:$G$1,0)) -> D | K8: =INDEX(products!$A$1:$G$49,MATCH(orders!$D8,products!$A$1:$A$49,0),MATCH(orders!K$1,products!$A$1:$G$1,0)) -> 0.5 | L8: =INDEX(products!$A$1:$G$49,MATCH(orders!$D8,products!$A$1:$A$49,0),MATCH(orders!L$1,products!$A$1:$G$1,0)) -> 7.29 | M8: =L8*E8 -> 21.87 | N8: {=_xlfn.SWITCH(I8,"rob","Robusta","exc","Excelsa","Ara","Arabica","Lib","Liberica","")} -> Excelsa | O8: {=_xlfn.SWITCH(J8,"M","Medium","D","Dark","L","Light")} -> Dark | P8: =_xlfn.XLOOKUP(ORDERS[[#This Row],[Customer ID]],customers!$A$1:$A$1001,customers!$I$1:$I$1001,,0) -> Yes
A9: SNZ-65340-705 | B9: 44701 | C9: 21134-81676-FR | D9: L-L-0.2 | E9: 1 | F9: =_xlfn.XLOOKUP(C9,customers!$A$1:$A$1001,customers!$B$1:$B$1001,,0) -> Melvin Wharfe | G9: =_xlfn.LET(_xlpm.val,_xlfn.XLOOKUP(C9,customers!$A$1:$A$1001,customers!$C$1:$C$1001,,0),IF(_xlpm.val=0,"",_xlpm.val)) | H9: =_xlfn.LET(_xlpm.val,_xlfn.XLOOKUP(C9,customers!$A$1:$A$1001,customers!$G$1:$G$1001,,0),IF(_xlpm.val=0,"",_xlpm.val)) -> Ireland | I9: =INDEX(products!$A$1:$G$49,MATCH(orders!$D9,products!$A$1:$A$49,0),MATCH(orders!I$1,products!$A$1:$G$1,0)) -> Lib | J9: =INDEX(products!$A$1:$G$49,MATCH(orders!$D9,products!$A$1:$A$49,0),MATCH(orders!J$1,products!$A$1:$G$1,0)) -> L | K9: =INDEX(products!$A$1:$G$49,MATCH(orders!$D9,products!$A$1:$A$49,0),MATCH(orders!K$1,products!$A$1:$G$1,0)) -> 0.2 | L9: =INDEX(products!$A$1:$G$49,MATCH(orders!$D9,products!$A$1:$A$49,0),MATCH(orders!L$1,products!$A$1:$G$1,0)) -> 4.755 | M9: =L9*E9 -> 4.755 | N9: {=_xlfn.SWITCH(I9,"rob","Robusta","exc","Excelsa","Ara","Arabica","Lib","Liberica","")} -> Liberica | O9: {=_xlfn.SWITCH(J9,"M","Medium","D","Dark","L","Light")} -> Light | P9: =_xlfn.XLOOKUP(ORDERS[[#This Row],[Customer ID]],customers!$A$1:$A$1001,customers!$I$1:$I$1001,,0) -> Yes
A10: EZT-46571-659 | B10: 43467 | C10: 03396-68805-ZC | D10: R-M-0.5 | E10: 3 | F10: =_xlfn.XLOOKUP(C10,customers!$A$1:$A$1001,customers!$B$1:$B$1001,,0) -> Guthrey Petracci | G10: =_xlfn.LET(_xlpm.val,_xlfn.XLOOKUP(C10,customers!$A$1:$A$1001,customers!$C$1:$C$1001,,0),IF(_xlpm.val=0,"",_xlpm.val)) -> gpetracci8@livejournal.com | H10: =_xlfn.LET(_xlpm.val,_xlfn.XLOOKUP(C10,customers!$A$1:$A$1001,customers!$G$1:$G$1001,,0),IF(_xlpm.val=0,"",_xlpm.val)) -> United States | I10: =INDEX(products!$A$1:$G$49,MATCH(orders!$D10,products!$A$1:$A$49,0),MATCH(orders!I$1,products!$A$1:$G$1,0)) -> Rob | J10: =INDEX(products!$A$1:$G$49,MATCH(orders!$D10,products!$A$1:$A$49,0),MATCH(orders!J$1,products!$A$1:$G$1,0)) -> M | K10: =INDEX(products!$A$1:$G$49,MATCH(orders!$D10,products!$A$1:$A$49,0),MATCH(orders!K$1,products!$A$1:$G$1,0)) -> 0.5 | L10: =INDEX(products!$A$1:$G$49,MATCH(orders!$D10,products!$A$1:$A$49,0),MATCH(orders!L$1,products!$A$1:$G$1,0)) -> 5.97 | M10: =L10*E10 -> 17.91 | N10: {=_xlfn.SWITCH(I10,"rob","Robusta","exc","Excelsa","Ara","Arabica","Lib","Liberica","")} -> Robusta | O10: {=_xlfn.SWITCH(J10,"M","Medium","D","Dark","L","Light")} -> Medium | P10: =_xlfn.XLOOKUP(ORDERS[[#This Row],[Customer ID]],customers!$A$1:$A$1001,customers!$I$1:$I$1001,,0) -> No
A11: NWQ-70061-912 | B11: 43713 | C11: 61021-27840-ZN | D11: R-M-0.5 | E11: 1 | F11: =_xlfn.XLOOKUP(C11,customers!$A$1:$A$1001,customers!$B$1:$B$1001,,0) -> Rodger Raven | G11: =_xlfn.LET(_xlpm.val,_xlfn.XLOOKUP(C11,customers!$A$1:$A$1001,customers!$C$1:$C$1001,,0),IF(_xlpm.val=0,"",_xlpm.val)) -> rraven9@ed.gov | H11: =_xlfn.LET(_xlpm.val,_xlfn.XLOOKUP(C11,customers!$A$1:$A$1001,customers!$G$1:$G$1001,,0),IF(_xlpm.val=0,"",_xlpm.val)) -> United States | I11: =INDEX(products!$A$1:$G$49,MATCH(orders!$D11,products!$A$1:$A$49,0),MATCH(orders!I$1,products!$A$1:$G$1,0)) -> Rob | J11: =INDEX(products!$A$1:$G$49,MATCH(orders!$D11,products!$A$1:$A$49,0),MATCH(orders!J$1,products!$A$1:$G$1,0)) -> M | K11: =INDEX(products!$A$1:$G$49,MATCH(orders!$D11,products!$A$1:$A$49,0),MATCH(orders!K$1,products!$A$1:$G$1,0)) -> 0.5 | L11: =INDEX(products!$A$1:$G$49,MATCH(orders!$D11,products!$A$1:$A$49,0),MATCH(orders!L$1,products!$A$1:$G$1,0)) -> 5.97 | M11: =L11*E11 -> 5.97 | N11: {=_xlfn.SWITCH(I11,"rob","Robusta","exc","Excelsa","Ara","Arabica","Lib","Liberica","")} -> Robusta | O11: {=_xlfn.SWITCH(J11,"M","Medium","D","Dark","L","Light")} -> Medium | P11: =_xlfn.XLOOKUP(ORDERS[[#This Row],[Customer ID]],customers!$A$1:$A$1001,customers!$I$1:$I$1001,,0) -> No
A12: BKK-47233-845 | B12: 44263 | C12: 76239-90137-UQ | D12: A-D-1 | E12: 4 | F12: =_xlfn.XLOOKUP(C12,customers!$A$1:$A$1001,customers!$B$1:$B$1001,,0) -> Ferrell Ferber | G12: =_xlfn.LET(_xlpm.val,_xlfn.XLOOKUP(C12,customers!$A$1:$A$1001,customers!$C$1:$C$1001,,0),IF(_xlpm.val=0,"",_xlpm.val)) -> fferbera@businesswire.com | H12: =_xlfn.LET(_xlpm.val,_xlfn.XLOOKUP(C12,customers!$A$1:$A$1001,customers!$G$1:$G$1001,,0),IF(_xlpm.val=0,"",_xlpm.val)) -> United States | I12: =INDEX(products!$A$1:$G$49,MATCH(orders!$D12,products!$A$1:$A$49,0),MATCH(orders!I$1,products!$A$1:$G$1,0)) -> Ara | J12: =INDEX(products!$A$1:$G$49,MATCH(orders!$D12,products!$A$1:$A$49,0),MATCH(orders!J$1,products!$A$1:$G$1,0)) -> D | K12: =INDEX(products!$A$1:$G$49,MATCH(orders!$D12,products!$A$1:$A$49,0),MATCH(orders!K$1,products!$A$1:$G$1,0)) -> 1 | L12: =INDEX(products!$A$1:$G$49,MATCH(orders!$D12,products!$A$1:$A$49,0),MATCH(orders!L$1,products!$A$1:$G$1,0)) -> 9.95 | M12: =L12*E12 -> 39.8 | N12: {=_xlfn.SWITCH(I12,"rob","Robusta","exc","Excelsa","Ara","Arabica","Lib","Liberica","")} -> Arabica | O12: {=_xlfn.SWITCH(J12,"M","Medium","D","Dark","L","Light")} -> Dark | P12: =_xlfn.XLOOKUP(ORDERS[[#This Row],[Customer ID]],customers!$A$1:$A$1001,customers!$I$1:$I$1001,,0) -> No
A13: VQR-01002-970 | B13: 44132 | C13: 49315-21985-BB | D13: E-L-2.5 | E13: 5 | F13: =_xlfn.XLOOKUP(C13,customers!$A$1:$A$1001,customers!$B$1:$B$1001,,0) -> Duky Phizackerly | G13: =_xlfn.LET(_xlpm.val,_xlfn.XLOOKUP(C13,customers!$A$1:$A$1001,customers!$C$1:$C$1001,,0),IF(_xlpm.val=0,"",_xlpm.val)) -> dphizackerlyb@utexas.edu | H13: =_xlfn.LET(_xlpm.val,_xlfn.XLOOKUP(C13,customers!$A$1:$A$1001,customers!$G$1:$G$1001,,0),IF(_xlpm.val=0,"",_xlpm.val)) -> United States | I13: =INDEX(products!$A$1:$G$49,MATCH(orders!$D13,products!$A$1:$A$49,0),MATCH(orders!I$1,products!$A$1:$G$1,0)) -> Exc | J13: =INDEX(products!$A$1:$G$49,MATCH(orders!$D13,products!$A$1:$A$49,0),MATCH(orders!J$1,products!$A$1:$G$1,0)) -> L | K13: =INDEX(products!$A$1:$G$49,MATCH(orders!$D13,products!$A$1:$A$49,0),MATCH(orders!K$1,products!$A$1:$G$1,0)) -> 2.5 | L13: =INDEX(products!$A$1:$G$49,MATCH(orders!$D13,products!$A$1:$A$49,0),MATCH(orders!L$1,products!$A$1:$G$1,0)) -> 34.155 | M13: =L13*E13 -> 170.775 | N13: {=_xlfn.SWITCH(I13,"rob","Robusta","exc","Excelsa","Ara","Arabica","Lib","Liberica","")} -> Excelsa | O13: {=_xlfn.SWITCH(J13,"M","Medium","D","Dark","L","Light")} -> Light | P13: =_xlfn.XLOOKUP(ORDERS[[#This Row],[Customer ID]],customers!$A$1:$A$1001,customers!$I$1:$I$1001,,0) -> Yes
... A1001: IRV-20769-219 | B1001: 44119 | C1001: 77131-58092-GE | D1001: E-M-0.2 | E1001: 3 | F1001: =_xlfn.XLOOKUP(C1001,customers!$A$1:$A$1001,customers!$B$1:$B$1001,,0) -> Vidovic Antonelli | G1001: =_xlfn.LET(_xlpm.val,_xlfn.XLOOKUP(C1001,customers!$A$1:$A$1001,customers!$C$1:$C$1001,,0),IF(_xlpm.val=0,"",_xlpm.val)) | H1001: =_xlfn.LET(_xlpm.val,_xlfn.XLOOKUP(C1001,customers!$A$1:$A$1001,customers!$G$1:$G$1001,,0),IF(_xlpm.val=0,"",_xlpm.val)) -> United Kingdom | I1001: =INDEX(products!$A$1:$G$49,MATCH(orders!$D1001,products!$A$1:$A$49,0),MATCH(orders!I$1,products!$A$1:$G$1,0)) -> Exc | J1001: =INDEX(products!$A$1:$G$49,MATCH(orders!$D1001,products!$A$1:$A$49,0),MATCH(orders!J$1,products!$A$1:$G$1,0)) -> M | K1001: =INDEX(products!$A$1:$G$49,MATCH(orders!$D1001,products!$A$1:$A$49,0),MATCH(orders!K$1,products!$A$1:$G$1,0)) -> 0.2 | L1001: =INDEX(products!$A$1:$G$49,MATCH(orders!$D1001,products!$A$1:$A$49,0),MATCH(orders!L$1,products!$A$1:$G$1,0)) -> 4.125 | M1001: =L1001*E1001 -> 12.375 | N1001: {=_xlfn.SWITCH(I1001,"rob","Robusta","exc","Excelsa","Ara","Arabica","Lib","Liberica","")} -> Excelsa | O1001: {=_xlfn.SWITCH(J1001,"M","Medium","D","Dark","L","Light")} -> Medium | P1001: =_xlfn.XLOOKUP(ORDERS[[#This Row],[Customer ID]],customers!$A$1:$A$1001,customers!$I$1:$I$1001,,0) -> Yes

Sheet customers
A1: Customer ID | B1: Customer Name | C1: Email | D1: Phone Number | E1: Address Line 1 | F1: City | G1: Country | H1: Postcode | I1: Loyalty Card
A2: 17670-51384-MA | B2: Aloisia Allner | C2: aallner0@lulu.com | D2: +1 (862) 817-0124 | E2: 57999 Pepper Wood Alley | F2: Paterson | G2: United States | H2: 7505 | I2: Yes
A3: 73342-18763-UW | B3: Piotr Bote | C3: pbote1@yelp.com | D3: +353 (913) 396-4653 | E3: 2112 Ridgeway Hill | F3: Crumlin | G3: Ireland | H3: D6W | I3: No
A4: 21125-22134-PX | B4: Jami Redholes | C4: jredholes2@tmall.com | D4: +1 (210) 986-6806 | E4: 5214 Bartillon Park | F4: San Antonio | G4: United States | H4: 78205 | I4: Yes
A5: 71253-00052-RN | B5: Dene Azema | C5: dazema3@facebook.com | D5: +1 (217) 418-0714 | E5: 27 Maywood Place | F5: Springfield | G5: United States | H5: 62711 | I5: Yes
A6: 23806-46781-OU | B6: Christoffer O' Shea | D6: +353 (698) 362-9201 | E6: 38980 Manitowish Junction | F6: Cill Airne | G6: Ireland | H6: N41 | I6: No
A7: 86561-91660-RB | B7: Beryle Cottier | D7: +1 (570) 289-7473 | E7: 2651 Stoughton Place | F7: Scranton | G7: United States | H7: 18505 | I7: No
A8: 65223-29612-CB | B8: Shaylynn Lobe | C8: slobe6@nifty.com | D8: +1 (937) 954-4541 | E8: 7005 Mariners Cove Place | F8: Dayton | G8: United States | H8: 45440 | I8: Yes
A9: 21134-81676-FR | B9: Melvin Wharfe | D9: +353 (507) 574-3034 | E9: 7 Straubel Road | F9: Kill | G9: Ireland | H9: P24 | I9: Yes
A10: 03396-68805-ZC | B10: Guthrey Petracci | C10: gpetracci8@livejournal.com | D10: +1 (310) 868-1842 | E10: 949 Paget Parkway | F10: Los Angeles | G10: United States | H10: 90045 | I10: No
A11: 61021-27840-ZN | B11: Rodger Raven | C11: rraven9@ed.gov | D11: +1 (213) 263-0288 | E11: 1 Reinke Avenue | F11: Los Angeles | G11: United States | H11: 90065 | I11: No
A12: 76239-90137-UQ | B12: Ferrell Ferber | C12: fferbera@businesswire.com | D12: +1 (408) 383-5302 | E12: 68 High Crossing Court | F12: San Jose | G12: United States | H12: 95160 | I12: No
A13: 49315-21985-BB | B13: Duky Phizackerly | C13: dphizackerlyb@utexas.edu | D13: +1 (408) 533-6012 | E13: 28643 Bluejay Crossing | F13: San Jose | G13: United States | H13: 95194 | I13: Yes
A14: 34136-36674-OM | B14: Rosaleen Scholar | C14: rscholarc@nyu.edu | D14: +1 (804) 420-0420 | E14: 80915 Montana Park | F14: Richmond | G14: United States | H14: 23285 | I14: No
A15: 39396-12890-PE | B15: Terence Vanyutin | C15: tvanyutind@wix.com | E15: 331 Bunting Hill | F15: Migrate | G15: United States | H15: 41905 | I15: No
A16: 95875-73336-RG | B16: Patrice Trobe | C16: ptrobee@wunderground.com | D16: +1 (314) 240-7896 | E16: 827 Declaration Plaza | F16: Saint Louis | G16: United States | H16: 63131 | I16: Yes
A17: 25473-43727-BY | B17: Llywellyn Oscroft | C17: loscroftf@ebay.co.uk | E17: 022 Roth Place | F17: Philadelphia | G17: United States | H17: 19172 | I17: No
A18: 99643-51048-IQ | B18: Minni Alabaster | C18: malabasterg@hexun.com | D18: +1 (971) 483-6255 | E18: 3 Charing Cross Trail | F18: Portland | G18: United States | H18: 97271 | I18: No
A19: 62173-15287-CU | B19: Rhianon Broxup | C19: rbroxuph@jimdo.com | D19: +1 (713) 663-1338 | E19: 83517 Thierer Court | F19: Houston | G19: United States | H19: 77240 | I19: No
A20: 57611-05522-ST | B20: Pall Redford | C20: predfordi@ow.ly | E20: 7337 Hayes Junction | F20: Caherconlish | G20: Ireland | H20: F45 | I20: Yes
A21: 76664-37050-DT | B21: Aurea Corradino | C21: acorradinoj@harvard.edu | D21: +1 (646) 202-5965 | E21: 698 Canary Terrace | F21: New York City | G21: United States | H21: 10060 | I21: Yes
A22: 84565-53984-SX | B22: Kendal Scardefield | D22: +353 (733) 405-3302 | E22: 3 Northridge Crossing | F22: Clondalkin | G22: Ireland | H22: D24 | I22: Yes
A23: 03090-88267-BQ | B23: Avrit Davidowsky | C23: adavidowskyl@netvibes.com | D23: +1 (616) 481-9962 | E23: 9 Warrior Junction | F23: Grand Rapids | G23: United States | H23: 49560 | I23: No
A24: 37651-47492-NC | B24: Annabel Antuk | C24: aantukm@kickstarter.com | D24: +1 (941) 740-6268 | E24: 77965 Lawn Park | F24: Punta Gorda | G24: United States | H24: 33982 | I24: Yes
A25: 95399-57205-HI | B25: Iorgo Kleinert | C25: ikleinertn@timesonline.co.uk | D25: +1 (360) 352-6598 | E25: 1 Morningstar Lane | F25: Vancouver | G25: United States | H25: 98682 | I25: Yes
A26: 24010-66714-HW | B26: Chrisy Blofeld | C26: cblofeldo@amazon.co.uk | D26: +1 (303) 936-3357 | E26: 013 Talisman Terrace | F26: Englewood | G26: United States | H26: 80150 | I26: No
A27: 07591-92789-UA | B27: Culley Farris | D27: +1 (941) 267-4822 | E27: 4 Mitchell Drive | F27: Punta Gorda | G27: United States | H27: 33982 | I27: Yes
A28: 49231-44455-IC | B28: Selene Shales | C28: sshalesq@umich.edu | D28: +1 (707) 881-5004 | E28: 74 Bultman Plaza | F28: Petaluma | G28: United States | H28: 94975 | I28: Yes
A29: 50124-88608-EO | B29: Vivie Danneil | C29: vdanneilr@mtv.com | D29: +353 (751) 346-0399 | E29: 5626 Darwin Avenue | F29: Tralee | G29: Ireland | H29: V92 | I29: No
A30: 00888-74814-UZ | B30: Theresita Newbury | C30: tnewburys@usda.gov | D30: +353 (803) 587-0026 | E30: 79526 Bultman Lane | F30: Clonskeagh | G30: Ireland | H30: D04 | I30: No
A31: 14158-30713-OB | B31: Mozelle Calcutt | C31: mcalcuttt@baidu.com | D31: +353 (928) 869-1762 | E31: 4389 Russell Way | F31: Rathwire | G31: Ireland | H31: Y25 | I31: Yes
A32: 51427-89175-QJ | B32: Adrian Swaine | D32: +1 (303) 486-9517 | E32: 95 Straubel Hill | F32: Aurora | G32: United States | H32: 80044 | I32: No
A33: 52082-49024-ON | B33: Ray Leivesley | C33: rleivesleyv@canalblog.com | D33: +1 (212) 535-7791 | E33: 91 Stephen Drive | F33: Jamaica | G33: United States | H33: 11407 | I33: No
A34: 04540-43685-DV | B34: Nelly Basezzi | C34: nbasezziw@webeden.co.uk | D34: +353 (125) 815-7345 | E34: 923 Mallard Junction | F34: Bailieborough | G34: Ireland | H34: C15 | I34: Yes
A35: 39123-12846-YJ | B35: Gallard Gatheral | C35: ggatheralx@123-reg.co.uk | E35: 40 Clemons Place | F35: Grand Forks | G35: United States | H35: 58207 | I35: No
A36: 44981-99666-XB | B36: Una Welberry | C36: uwelberryy@ebay.co.uk | D36: +44 (392) 503-8132 | E36: 40915 Schlimgen Park | F36: Upton | G36: United Kingdom | H36: DN21 | I36: Yes
A37: 24825-51803-CQ | B37: Faber Eilhart | C37: feilhartz@who.int | D37: +1 (304) 510-6095 | E37: 6966 Victoria Street | F37: Charleston | G37: United States | H37: 25362 | I37: No
A38: 77634-13918-GJ | B38: Zorina Ponting | C38: zponting10@altervista.org | D38: +1 (501) 172-1476 | E38: 7118 Holmberg Court | F38: Little Rock | G38: United States | H38: 72204 | I38: No
A39: 13694-25001-LX | B39: Silvio Strase | C39: sstrase11@booking.com | D39: +1 (303) 579-8015 | E39: 5 Forest Lane | F39: Denver | G39: United States | H39: 80291 | I39: No
A40: 08523-01791-TI | B40: Dorie de la Tremoille | C40: dde12@unesco.org | D40: +1 (612) 492-5160 | E40: 0817 Dennis Street | F40: Minneapolis | G40: United States | H40: 55458 | I40: No
...

Sheet products
A1: Product ID | B1: Coffee Type | C1: Roast Type | D1: Size | E1: Unit Price | F1: Price per 100g | G1: Profit
A2: A-L-0.2 | B2: Ara | C2: L | D2: 0.2 | E2: 3.885 | F2: 1.9425 | G2: 0.34965
A3: A-L-0.5 | B3: Ara | C3: L | D3: 0.5 | E3: 7.77 | F3: 1.554 | G3: 0.6993
A4: A-L-1 | B4: Ara | C4: L | D4: 1 | E4: 12.95 | F4: 1.295 | G4: 1.1655
A5: A-L-2.5 | B5: Ara | C5: L | D5: 2.5 | E5: 29.785 | F5: 1.1914 | G5: 2.68065
A6: A-M-0.2 | B6: Ara | C6: M | D6: 0.2 | E6: 3.375 | F6: 1.6875 | G6: 0.30375
A7: A-M-0.5 | B7: Ara | C7: M | D7: 0.5 | E7: 6.75 | F7: 1.35 | G7: 0.6075
A8: A-M-1 | B8: Ara | C8: M | D8: 1 | E8: 11.25 | F8: 1.125 | G8: 1.0125
A9: A-M-2.5 | B9: Ara | C9: M | D9: 2.5 | E9: 25.875 | F9: 1.035 | G9: 2.32875
A10: A-D-0.2 | B10: Ara | C10: D | D10: 0.2 | E10: 2.985 | F10: 1.4925 | G10: 0.26865
A11: A-D-0.5 | B11: Ara | C11: D | D11: 0.5 | E11: 5.97 | F11: 1.194 | G11: 0.5373
A12: A-D-1 | B12: Ara | C12: D | D12: 1 | E12: 9.95 | F12: 0.995 | G12: 0.8955
A13: A-D-2.5 | B13: Ara | C13: D | D13: 2.5 | E13: 22.885 | F13: 0.9154 | G13: 2.05965
... A49: E-D-2.5 | B49: Exc | C49: D | D49: 2.5 | E49: 27.945 | F49: 1.1178 | G49: 3.07395
